Workbook

Sheet CyclomaticAverages
A1: Model | B1: Cyclomatic_Given | C1: Codex | D1: GeminiPro | E1: Falcon | F1: Llama2
A2: BLEU | B2: 1 | C2: 0.41614024 | D2: 0.37248116 | E2: 0.38622416 | F2: 0.39496041
B3: 2 | C3: 0.41688916 | D3: 0.40727849 | E3: 0.41709969 | F3: 0.41869637
B4: 3 | C4: 0.4104931 | D4: 0.40939575 | E4: 0.41759089 | F4: 0.41880065
B5: 4 | C5: 0.42500064 | D5: 0.39663407 | E5: 0.4164129 | F5: 0.42108496
B6: 5 | C6: 0.48105117 | D6: 0.47414246 | E6: 0.49252909 | F6: 0.49303114
B7: 6 | C7: 0.48519805 | D7: 0.47823395 | E7: 0.48547366 | F7: 0.48825972
A8: Pearson | C8: =PEARSON(B2:B7,C2:C7) -> 0.85774499 | D8: =PEARSON(B2:B7,D2:D7) -> 0.8859595 | E8: =PEARSON(B2:B7,E2:E7) -> 0.89886745 | F8: =PEARSON(B2:B7,F2:F7) -> 0.90074073
A9: ChrF | B9: 1 | C9: 63.584402 | D9: 63.792333 | E9: 65.504643 | F9: 65.97581
B10: 2 | C10: 66.268963 | D10: 66.766215 | E10: 63.766488 | F10: 64.022218
B11: 3 | C11: 67.359903 | D11: 65.674617 | E11: 67.502397 | F11: 67.574394
B12: 4 | C12: 65.220079 | D12: 62.486649 | E12: 66.555334 | F12: 66.586708
B13: 5 | C13: 74.257392 | D13: 71.898597 | E13: 72.257985 | F13: 72.698439
B14: 6 | C14: 72.137179 | D14: 72.03883 | E14: 74.425508 | F14: 74.538181
A15: Pearson | C15: =PEARSON(B9:B14,C9:C14) -> 0.82866777 | D15: =PEARSON(B9:B14,D9:D14) -> 0.70630878 | E15: =PEARSON(B9:B14,E9:E14) -> 0.89503614 | F15: =PEARSON(B9:B14,F9:F14) -> 0.87964961
A16: Cosine | B16: 1 | C16: 0.96576288 | D16: 0.96421827 | E16: 0.96595549 | F16: 0.96620298
B17: 2 | C17: 0.98597989 | D17: 0.98556271 | E17: 0.98602506 | F17: 0.98602704
B18: 3 | C18: 0.97903631 | D18: 0.97778179 | E18: 0.99319799 | F18: 0.97952954
B19: 4 | C19: 0.98898154 | D19: 0.98851444 | E19: 0.98903193 | F19: 0.98925469
B20: 5 | C20: 0.98292425 | D20: 0.982244 | E20: 0.98301208 | F20: 0.98313314
B21: 6 | C21: 0.99300155 | D21: 0.99253275 | E21: 0.99922025 | F21: 0.99330891
A22: Pearson | C22: =PEARSON(B16:B21,C16:C21) -> 0.76612273 | D22: =PEARSON(B16:B21,D16:D21) -> 0.76096818 | E22: =PEARSON(B16:B21,E16:E21) -> 0.71979662 | F22: =PEARSON(B16:B21,F16:F21) -> 0.77060747
A23: Levenshtein_Char | B23: 1 | C23: 16.816327 | D23: 17.387755 | E23: 16.591837 | F23: 16.428571
B24: 2 | C24: 10.79096 | D24: 14.013245 | E24: 12.910714 | F24: 12.75
B25: 3 | C25: 13.066225 | D25: 14.125 | E25: 12.821192 | F25: 12.602649
B26: 4 | C26: 13.160714 | D26: 10.12987 | E26: 9.038961 | F26: 8.6623377
B27: 5 | C27: 7.484375 | D27: 8.46875 | E27: 7.34375 | F27: 7.25
B28: 6 | C28: 9.1298701 | D28: 11.836158 | E28: 10.446328 | F28: 10.19209
A29: Pearson | C29: =PEARSON(B23:B28,C23:C28) -> -0.77513666 | D29: =PEARSON(B23:B28,D23:D28) -> -0.81001515 | E29: =PEARSON(B23:B28,E23:E28) -> -0.83217199 | F29: =PEARSON(B23:B28,F23:F28) -> -0.834348
A30: Levenshtein_Word | B30: 1 | C30: 1.2028986 | D30: 1.2608696 | E30: 1.2002899 | F30: 1.173913
B31: 2 | C31: 1.1449275 | D31: 1.173913 | E31: 1.1542145 | F31: 1.0869565
B32: 3 | C32: 1.0258065 | D32: 1.0387097 | E32: 1.0355426 | F32: 1.0387097
B33: 4 | C33: 1.0387097 | D33: 1.0338706 | E33: 1.0318769 | F33: 1.0258065
B34: 5 | C34: 1.0461728 | D34: 1.0061728 | E34: 1.0061728 | F34: 1.0051226
B35: 6 | C35: 1.0681481 | D35: 1.0993827 | E35: 1.0098148 | F35: 1.0090123
A36: Pearson | C36: =PEARSON(B30:B35,C30:C35) -> -0.72520387 | D36: =PEARSON(B30:B35,D30:D35) -> -0.715815 | E36: =PEARSON(B30:B35,E30:E35) -> -0.90294514 | F36: =PEARSON(B30:B35,F30:F35) -> -0.8960167
A37: Meteor | B37: 1 | C37: 0.61542067 | D37: 0.59229009 | E37: 0.61837835 | F37: 0.62677271
B38: 2 | C38: 0.6603117 | D38: 0.65302359 | E38: 0.6621327 | F38: 0.66329487
B39: 3 | C39: 0.60948415 | D39: 0.59348999 | E39: 0.61317832 | F39: 0.61593352
B40: 4 | C40: 0.66429886 | D40: 0.64168109 | E40: 0.66626354 | F40: 0.66861998
...

Sheet Pearson Correlation
A1: Pearson Correlation btw Cyclomatic Complexity and Robustness R^o
A2: Similarity Metric | B2: =CyclomaticAverages!C1 -> Codex | C2: =CyclomaticAverages!D1 -> GeminiPro | D2: =CyclomaticAverages!E1 -> Falcon | E2: =CyclomaticAverages!F1 -> Llama2
A3: =CyclomaticAverages!$A$2 -> BLEU | B3: =CyclomaticAverages!C8 -> 0.85774499 | C3: =CyclomaticAverages!D8 -> 0.8859595 | D3: =CyclomaticAverages!E8 -> 0.89886745 | E3: =CyclomaticAverages!F8 -> 0.90074073
A4: =CyclomaticAverages!$A$9 -> ChrF | B4: =CyclomaticAverages!C15 -> 0.82866777 | C4: =CyclomaticAverages!D15 -> 0.70630878 | D4: =CyclomaticAverages!E15 -> 0.89503614 | E4: =CyclomaticAverages!F15 -> 0.87964961
A5: =CyclomaticAverages!$A$16 -> Cosine | B5: =CyclomaticAverages!C22 -> 0.76612273 | C5: =CyclomaticAverages!D22 -> 0.76096818 | D5: =CyclomaticAverages!E22 -> 0.71979662 | E5: =CyclomaticAverages!F22 -> 0.77060747
A6: =CyclomaticAverages!$A$23 -> Levenshtein_Char | B6: =CyclomaticAverages!C29 -> -0.77513666 | C6: =CyclomaticAverages!D29 -> -0.81001515 | D6: =CyclomaticAverages!E29 -> -0.83217199 | E6: =CyclomaticAverages!F29 -> -0.834348
A7: =CyclomaticAverages!$A$30 -> Levenshtein_Word | B7: =CyclomaticAverages!C36 -> -0.72520387 | C7: =CyclomaticAverages!D36 -> -0.715815 | D7: =CyclomaticAverages!E36 -> -0.90294514 | E7: =CyclomaticAverages!F36 -> -0.8960167
A8: =CyclomaticAverages!$A$37 -> Meteor | B8: =CyclomaticAverages!C43 -> 0.81714263 | C8: =CyclomaticAverages!D43 -> 0.80568896 | D8: =CyclomaticAverages!E43 -> 0.81876786 | E8: =CyclomaticAverages!F43 -> 0.81156353
A9: =CyclomaticAverages!$A$44 -> RougeL | B9: =CyclomaticAverages!C50 -> 0.84833437 | C9: =CyclomaticAverages!D50 -> 0.8837584 | D9: =CyclomaticAverages!E50 -> 0.84768383 | E9: =CyclomaticAverages!F50 -> 0.84977802
A10: =CyclomaticAverages!$A$51 -> RougeN | B10: =CyclomaticAverages!C57 -> 0.82430156 | C10: =CyclomaticAverages!D57 -> 0.8698943 | D10: =CyclomaticAverages!E57 -> 0.77001609 | E10: =CyclomaticAverages!F57 -> 0.79615217
A11: =CyclomaticAverages!$A$58 -> Euclidean | B11: =CyclomaticAverages!C64 -> -0.97948952 | C11: =CyclomaticAverages!D64 -> -0.98694267 | D11: =CyclomaticAverages!E64 -> -0.98728658 | E11: =CyclomaticAverages!F64 -> -0.98494093
A12: =CyclomaticAverages!$A$65 -> RoBERTa | B12: =CyclomaticAverages!C71 -> 0.99236265 | C12: =CyclomaticAverages!D71 -> 0.95935583 | D12: =CyclomaticAverages!E71 -> 0.93680065 | E12: =CyclomaticAverages!F71 -> 0.940401
